Workbook
Name __________T999999: '[1]Dis. Schedule'!#REF!
Name _________T999999: '[1]Dis. Schedule'!#REF!
Name ________T999999: '[1]Dis. Schedule'!#REF!
Name _______T999999: '[1]Dis. Schedule'!#REF!
Name ______T999999: '[2]Dis. Schedule'!#REF!
Name _____T999999: '[2]Dis. Schedule'!#REF!
Name ____T999999: '[2]Dis. Schedule'!#REF!
Name ___T999999: '[2]Dis. Schedule'!#REF!
Name __T999999: '[2]Dis. Schedule'!#REF!
Name _amt1: #REF!
Name _amt1: #REF!
Name _amt5: #REF!
Name _amt5: #REF!
Name _nmw1: [3]lead!$B$2
Name _nmw1: [4]lead!$B$2
Name _qty14: [5]Measurement!$H$72
Name _qty14: [6]Measurement!$H$72
Name _qty15: [5]Measurement!$H$85
Name _qty15: [6]Measurement!$H$85
Name _qty16: [5]Measurement!$H$91
Name _qty16: [6]Measurement!$H$91
Name _qty17: [5]Measurement!$H$99
Name _qty17: [6]Measurement!$H$99
Name _qty18: [5]Measurement!$H$108
Name _qty18: [6]Measurement!$H$108
Name _qty7: '[7]mes-4'!#REF!
Name _qty7: '[8]mes-4'!#REF!
Name _T999999: '[1]Dis. Schedule'!#REF!
Name _TM1: #REF!
Name _TM1: #REF!
Name _TM10: #REF!
Name _TM10: #REF!
Name _TM11: #REF!
Name _TM11: #REF!
Name _TM12: #REF!
Name _TM12: #REF!
Name _TM2: #REF!
Name _TM2: #REF!
Name _TM3: #REF!
Name _TM3: #REF!
Name _TM4: #REF!
Name _TM4: #REF!
Name _TM5: #REF!
Name _TM5: #REF!
Name _TM6: #REF!
Name _TM6: #REF!
Name _TM7: #REF!
Name _TM7: #REF!
Name _TM8: #REF!
Name _TM8: #REF!
Name _TM9: #REF!
Name _TM9: #REF!
Name a340.: #REF!
Name a340.: #REF!
Name AK: #REF!
Name AK: #REF!
Name Bust: #REF!
Name Bust: #REF!
Name Bust: #REF!
Name Continue: #REF!

Sheet GD
A1: ESTIMATE
A4: Division | D4: : | E4: Vadodara Electrical Division, Vadodara.
A6: Fund Head | D6: : | E6: 2075 VVIP/DEPOSIT/GRANTED
A8: Major Head | D8: :
A10: Minor Head | D10: :
A12: Sub Head | D12: :
A14: Estimate framed in the office of the Executive Engineer, Vadodara Electrical Division,Vadodara, for the probable expenditure to be incurred in Providing Temporary EI with Standby DG Set for virtual P.M. Programme of property Card Distribution at BAPS Swaminarayan Temple at Dabhoi Dist.Vadodara.
G17: Total Rs. | H17: =EST!J39 -> 168785.7
A19: Administ. Approved Under | D19: :
A21: Technical Sanction Under | D21: :
A23: Estimate Prepared by | D23: : | E23: Smt. Shilpa Prajapati (A.E)
E24: Vadodara Elect. Sub Division, Vadodara.
A26: Estimate Checked by | D26: :
E27: Vadodara Elect. Division, Vadodara.
A29: Call/Authority | D29: : | E29: letter of Colllector Ofice , Vadodara .o/w no. ADM/MYSE/ VASHI/152/2025 Dt: 16-01-2025
A34: General Description
A35: This estimate is framed to meet with the probable cost of Providing Providing Temporary EI with Standby DG Set for virtual P.M. Programme of property Card Distribution at BAPS Swaminarayan Temple at Dabhoi Dist.Vadodara.

Sheet EST
A1: ESTIMATE
A3: Name of Work | B3: Providing Temporary EI with Standby DG Set for virtual P.M. Programme of property Card Distribution at BAPS Swaminarayan Temple at Dabhoi Dist.Vadodara.
A7: SR. NO. | B7: Quantity | C7: SOR NO. | D7: Item Description | E7: Per | I7: Rate as Per RA | J7: Amount
A8: 1 | B8: 52 | C8: 11-1-48. | D8: Hire charges for LED Flood Light Fittings with High Power White LEDs wattage of 1 Watt and above assemble on single MCPCB, efficiency more than 130 Im/w and corrosion free high pressure die cast aluminium housing with smooth finish powder coated and heat sink extruded aluminium with diffuser and Polycarbonate optics/lenses with company mark/name engraved or embossed 120 to 300 V, Power factor more than 0.95, THD<10%, CCT 5000 K to 5700K, Uniformity ratio >0.45, Luminaire efficiency > 85 Lumens/Watt, LED driver efficiency >85%. CREE/OSRAM/PHILLIPS Lumileds /NICHIA/SEOUL/BridgeLux(U.S.A) make LED used for luminaire. (Each fitting required LM-79 & LM-80 Certificates) (B) Flood Light (IP-65), Surge -4KV ( e ) Above 150 watts to 240 watts Cat-III | E8: 1st Day /Nos | I8: ='RA '!H5 -> 1243.5625 | J8: =I8*B8 -> 64665.25
A9: 2 | B9: 8 | C9: 11-1-3 | D9: Hire charges for providing erecting and dismantling temporary illumination consisting of the LED tube lights 22 watt minimum complete withlead wires | I9: ='RA '!H6 -> 21.4625 | J9: =I9*B9 -> 171.7
A10: 3 | B10: 8 | C10: '11-1-16 | D10: Higher charges for providing erecting and Removing after use of good running condition 300 mm/ 400 mm size low noise oscillation type pedestal fan of good condition. | I10: ='RA '!H7 -> 308.05 | J10: =I10*B10 -> 2464.4
A11: 4 | B11: 10 | C11: '11-1-17 | D11: Hire charges for providing, & erecting and dismantling after use of good running condition 600mm/900mm heavy duty air-circulator pedestal type fan of good running condition. | I11: ='RA '!H8 -> 267.65 | J11: =I11*B11 -> 2676.5
A12: 5 | B12: 20 | C12: 11-1-19. | D12: Hire charges for providing for temporary plug point with 5/15Amp plug switch combined, erected in wooden board complete | E12: 1st Day /Nos | I12: ='RA '!H9 -> 27.775 | J12: =I12*B12 -> 555.5
A13: 6 | B13: 4 | C13: 11-1-20/P | D13: Hire charges for providing erecting and dismantling after use in good running condition with necessary interconnecting wire/cable on panel board. (P) Distribution Boards 3 phase 440V 6A/32A (i) 4 - 6 Way | E13: 1st Day /Nos | J13: =I13*B13 -> 0
A14: 7 | B14: 2 | D14: (A) D.P. Switch 16A/32A, 230V | E14: 1st Day /Nos | I14: ='RA '!H10 -> 34.0875 | J14: =I14*B14 -> 68.175
A15: 8 | B15: 2 | D15: (P) Distribution Boards 3 phase 440V 6A/32A (i) 4 - 6 Way | I15: ='RA '!H11 -> 97.2125 | J15: =I15*B15 -> 194.425
A16: 9 | B16: 2 | D16: (Q) Distribution Boards 3 phase 440V 6A/32A (ii) 8-12 Way | I16: ='RA '!H12 -> 171.7 | J16: =I16*B16 -> 343.4
A17: 10 | B17: 2 | C17: 11-1-21 | D17: Hire charges for providing erecting and dismantling after use in good running condition. Section pillar fabricated from 16 SWG thick M.S. Sheet with 40 x 40 x 6 mm thick angle iron legs with 12 mm thick bakelite / wooden sheet erected complete with following sizes (b) Section pillar having size 75 x 60 x 45 | I17: ='RA '!H13 -> 321.9375 | J17: =I17*B17 -> 643.875
A18: 11 | B18: 7 | C18: 11-1-49. | D18: Hire charges for providing & dismantling earth pit of minimum bore dia.150mm size approved make Earthing Electrode consisting Pipe-in-Pipe Technology as per IS 3043-1987 made of corrosion free G.I.Pipes having Outer pipe dia of 50mm having 80-200 Micron galvanizing, Inner pipe dia of 25 mm having 200-250 Micron galvanizing, connection terminal dia of 12mm with constant ohmic value surrounded by highly conductive compound with high charge dissipation suitable for following type of applications(a) For Electrical Installation up to 440V in normal soil Length of pipe - 1 Mtr Back filling compound - 1 Nos Bag of 15 Kg. | I18: ='RA '!H14 -> 802.95 | J18: =I18*B18 -> 5620.65
A19: 12 | B19: 550 | C19: 11-1-24 | D19: Hire charges for providing, erecting & dismantling after use of good running condition for PVC copper /Aluminium wire mains with suitable copper PVC 1.5 / 2.5 Sq.mm earth wire of following size | I19: ='RA '!H15 -> 3.7875 | J19: =I19*B19 -> 2083.125
A20: 13 | B20: 185 | D20: (A) 2 wire 1 /1.5 / 2.5 Sq.mm Copper | I20: ='RA '!H16 -> 5.05 | J20: =I20*B20 -> 934.25
A21: 14 | B21: 165 | D21: (C) 2 wire 4 /6 Sq.mm Copper | I21: ='RA '!H17 -> 13.8875 | J21: =I21*B21 -> 2291.4375
A22: 15 | B22: 185 | D22: (I) 4 wire 10 Sq.mm Copper | I22: ='RA '!H18 -> 17.675 | J22: =I22*B22 -> 3269.875
C23: 11-1-25 | D23: Hire charges for providing erecting as per direction of Engineer in charge dismantling after use of good running condition for temporary power supply the XLPE insulated armoured cable Aluminium conductor of following size. | J23: =I23*B23 -> 0
A24: 16 | B24: 140 | D24: (B) 4 Core 4 / 6 / 10 Sq.mm | I24: ='RA '!H18 -> 17.675 | J24: =I24*B24 -> 2474.5
A25: 17 | B25: 140 | D25: (E) 3 1/2 Core 50 / 70 Sq.mm | I25: ='RA '!H19 -> 32.825 | J25: =I25*B25 -> 4595.5
C26: 11-1-28 | D26: Hire charges for providing, erecting with necessary connection and dismantling after user of good running ELCBs/RCCBs conforming to IS 12640 and having sensitivity of 30 ma and short circuit withstand capacity of 6 KA and Suitable for operation on 3 Phase and neutral 415V having characteristic of quick action & tripping with all advance feature & do not incorporate any electronic component for following Max rating | J26: =I26*B26 -> 0
A27: 18 | B27: 2 | D27: (A) 40 Amps FP [Cat.II] | I27: ='RA '!H20 -> 171.7 | J27: =I27*B27 -> 343.4
A28: 19 | B28: 1 | D28: (B) 63 Amps FP [Cat.II] | I28: ='RA '!H21 -> 204.525 | J28: =I28*B28 -> 204.525
C29: 11-1-30 | D29: Hire charges for providing, erecting with necessary connection and dismantling after user of good running Supplying & erecting approved make Four Pole 415V change over switch interior for panel mounting with operating mechanism A.C. 23 duty confirming to I. S.S. for | J29: =I29*B29 -> 0
A30: 20 | B30: 1 | D30: (D) 200 A [Cat.II] | I30: ='RA '!H22 -> 427.9875 | J30: =I30*B30 -> 427.9875
A31: 21 | B31: 1 | C31: 11-01-31. | D31: Hire charges for Providing & erecting weather proof, dust & vermin proof / floor mounted Front operated outdoor type cubical Panel board having IP 64 protection made from 14 SWG thick CRC MS sheet for outer body and doors, 16 SWG thick CRC MS Sheet for internal partition with neccessary supporting angles, flats including cutting.bending , drilling, welding revetting, with internal Partition and cable alley as per requirement & instruction of Engineer in charge with SUPPLY AND ERECTION OF of following type switchgears /busbars with suitable size of inter connecting PVC copper wire/ copper strips,rubber grommets,rib,earth bus and earth bolt, foundation flange- bolts - base plates, sufficient Nos. of Hinged doors, handles with locking arrangement &rubber gasket complete .The panel shall be painted with epoxy powder coating and have Cu. Busbar strips . Each bus bar should insulated by color coded sleeve. WITH PHASE INDICATING Lamps--- Digital Multi function meter - Voltage, Amperes & Frequency only) with CTs coils) Each panel will contain earth bus and earth bolts with danger notice board. | I31: ='RA '!H23 -> 8559.75 | J31: =I31*B31 -> 8559.75
D32: [C] Power Distribution Cubical Panel with main incomer 125A also with change over switch of 125A TPN MCCB - 1 Nos., 200 A Alum. Busbar, Outgoing 16A SP MCB 10 KA - 6 Nos, [Panel size 800mm H x 600 mm W x 350 mm D] | J32: =I32*B32 -> 0
A33: 22 | B33: 6 | C33: 11-1-39 | D33: Hire charges for providing erecting and dismantling after use of good running Tower type /Split type Air-Conditioning machine complete with erection gas charging etc. (a) 1.5-2 ton for one day as per instruction of engineer. | I33: ='RA '!H24 -> 2461.875 | J33: =I33*B33 -> 14771.25
A34: 23 | B34: 1 | C34: 11-2-2 | D34: Hire charges for440V A.C generating set following capacity with necessary fuel, mains, switchgears & accessories complete running on load / no load with acoustic sound proof enclosure etc as per requirement. With transportation charges up to 30 kms. | I34: ='RA '!H25 -> 25679.25 | J34: =I34*B34 -> 25679.25
D35: [F] 125 KVA | J35: =I35*B35 -> 0
D37: Total Rs. | J37: =SUM(J8:J35) -> 143038.72
D38: 18% GST | J38: =J37*18% -> 25746.97
D39: Say Rs. | J39: =J37+J38 -> 168785.7
A46: Assistant Engineer | D46: Dy.Executive Engineer | I46: Executive Engineer
A47: Vadodara Elect. Sub Division | D47: Vadodara Elect. Sub Division | I47: Vadodara Elect Division
A48: R&B Department ,Vadodara | D48: R&B Department ,Vadodara | I48: R&B Department ,Vadodara

Sheet RA 
A1: Rate Analysis
A3: Name of Work :- | C3: Providing Temporary EI with Standby DG Set for virtual P.M. Programme of property Card Distribution at BAPS Swaminarayan Temple at Dabhoi Dist.Vadodara.
A4: Sr.No | B4: SOR NO. | C4: Description of Item | D4: SOR Rate Rs. | E4: (1st Day) Rate with 1%LC | F4: (1st Day) Rate with 1%LC | G4: 25% of 1st Day(rehersal) | H4: Total Rate
A5: 1 | B5: 11-1-48. | C5: flood light | D5: 985 | E5: =D5*1% -> 9.85 | F5: =D5+E5 -> 994.85 | G5: =F5*25% -> 248.7125 | H5: =F5+G5 -> 1243.5625
A6: 1 | B6: 11-1-19. | C6: led tube light | D6: 17 | E6: =D6*1% -> 0.17 | F6: =D6+E6 -> 17.17 | G6: =F6*25% -> 4.2925 | H6: =F6+G6 -> 21.4625
C7: pedestl type Fan low noise | D7: 244 | E7: =D7*1% -> 2.44 | F7: =D7+E7 -> 246.44 | G7: =F7*25% -> 61.61 | H7: =F7+G7 -> 308.05
C8: pedestl type Fan heeavy duty | D8: 212 | E8: =D8*1% -> 2.12 | F8: =D8+E8 -> 214.12 | G8: =F8*25% -> 53.53 | H8: =F8+G8 -> 267.65
C9: 5/15Amp plug | D9: 22 | E9: =D9*1% -> 0.22 | F9: =D9+E9 -> 22.22 | G9: =F9*25% -> 5.555 | H9: =F9+G9 -> 27.775
C10: D.P. Switch 16A/32A | D10: 27 | E10: =D10*1% -> 0.27 | F10: =D10+E10 -> 27.27 | G10: =F10*25% -> 6.8175 | H10: =F10+G10 -> 34.0875
C11: Distribution Boards 3 phase 440V 6A/32A (i) 4 - 6 Way | D11: 77 | E11: =D11*1% -> 0.77 | F11: =D11+E11 -> 77.77 | G11: =F11*25% -> 19.4425 | H11: =F11+G11 -> 97.2125
A12: 2 | B12: 11-1-20/P. | C12: (ii) 8-12 Way | D12: 136 | E12: =D12*1% -> 1.36 | F12: =D12+E12 -> 137.36 | G12: =F12*25% -> 34.34 | H12: =F12+G12 -> 171.7
C13: Section pillar fabricated 40 x 40 x 6 | D13: 255 | E13: =D13*1% -> 2.55 | F13: =D13+E13 -> 257.55 | G13: =F13*25% -> 64.3875 | H13: =F13+G13 -> 321.9375
C14: pipe type earthing | D14: 636 | E14: =D14*1% -> 6.36 | F14: =D14+E14 -> 642.36 | G14: =F14*25% -> 160.59 | H14: =F14+G14 -> 802.95
C15: (A) 2 wire 1 /1.5 / 2.5 Sq.mm Copper | D15: 3 | E15: =D15*1% -> 0.03 | F15: =D15+E15 -> 3.03 | G15: =F15*25% -> 0.7575 | H15: =F15+G15 -> 3.7875
C16: (C) 2 wire 4 /6 Sq.mm Copper | D16: 4 | E16: =D16*1% -> 0.04 | F16: =D16+E16 -> 4.04 | G16: =F16*25% -> 1.01 | H16: =F16+G16 -> 5.05
C17: (I) 4 wire 10 Sq.mm Copper | D17: 11 | E17: =D17*1% -> 0.11 | F17: =D17+E17 -> 11.11 | G17: =F17*25% -> 2.7775 | H17: =F17+G17 -> 13.8875
C18: (B) 4 Core 4 / 6 / 10 Sq.mm | D18: 14 | E18: =D18*1% -> 0.14 | F18: =D18+E18 -> 14.14 | G18: =F18*25% -> 3.535 | H18: =F18+G18 -> 17.675
C19: (E) 3 1/2 Core 50 / 70 Sq.mm | D19: 26 | E19: =D19*1% -> 0.26 | F19: =D19+E19 -> 26.26 | G19: =F19*25% -> 6.565 | H19: =F19+G19 -> 32.825
C20: ELCB(A) 40 Amps FP [Cat.II] | D20: 136 | E20: =D20*1% -> 1.36 | F20: =D20+E20 -> 137.36 | G20: =F20*25% -> 34.34 | H20: =F20+G20 -> 171.7
C21: ELCB(B) 63 Amps FP [Cat.II] | D21: 162 | E21: =D21*1% -> 1.62 | F21: =D21+E21 -> 163.62 | G21: =F21*25% -> 40.905 | H21: =F21+G21 -> 204.525
C22: CHANGE OVER SWITCH(D) 200 A [Cat.II] | D22: 339 | E22: =D22*1% -> 3.39 | F22: =D22+E22 -> 342.39 | G22: =F22*25% -> 85.5975 | H22: =F22+G22 -> 427.9875
C23: [C] Power Distribution Cubical Panel with main incomer 125A also with change over switch of 125A TPN MCCB - 1 Nos., 200 A Alum. Busbar, Outgoing 16A SP MCB 10 KA - 6 Nos, [Panel size 800mm H x 600 mm W x 350 mm D] | D23: 6780 | E23: =D23*1% -> 67.8 | F23: =D23+E23 -> 6847.8 | G23: =F23*25% -> 1711.95 | H23: =F23+G23 -> 8559.75
C24: TOWER TYPE AC | D24: 1950 | E24: =D24*1% -> 19.5 | F24: =D24+E24 -> 1969.5 | G24: =F24*25% -> 492.375 | H24: =F24+G24 -> 2461.875
C25: D.G. SET ( 125 KVA) | D25: 20340 | E25: =D25*1% -> 203.4 | F25: =D25+E25 -> 20543.4 | G25: =F25*25% -> 5135.85 | H25: =F25+G25 -> 25679.25
B29: Assistant Engineer | D29: Dy.Executive Engineer | G29: Executive Engineer
B30: Vadodara Elec. Sub Division | D30: Vadodara Elect. Sub Division | G30: Vadodara Elect Division
B31: R&B Department ,Vadodara | D31: R&B Department ,Vadodara | G31: R&B Department ,Vadodara

Sheet LED TV
B2: CHAPTER-XI TEMPORARY ILLUMINATION,A/C,PUBLIC ADDRESS AUDIO/ VIDEO & STANDBY POWER SYSTEM
B3: (Rates included GST/Service Tax)
B4: NOTES
B5: 1 | C5: The rates for temporary D.G,sound ,E.I. ,A.C. , LED, TV, Multi media are applicable for 1st day including preparatory & testing period & no additional amount shall be paid for that but for rehearsal if ask by authority, additional amount shall be paid 25% of first day rental charges.
B6: 2 | C6: (i) For the second day of function , 40% of first day rent shall be considered. (ii) For each additional day after Second day of function but not exceeding 15 days, 15% of first day rental cost will be considered.
B7: 3 | C7: After 15 days 5% of 1st day rental cost will be limited do 80% of full rate of newly purchased equipments .For more than above days,it is necessary to have consent letter of administrative authority.
B8: 4 | C8: Testing of all temporary arrangement will be positively given before 12 hours start of function or rehearsal (if ask by concerned Authority) .
B9: 5 | C9: For D.G. set, rental rates are applicable for first day. (1)For next subsequently 7 days ,90% of first day rental charges will be applied (2)from 8th day ,80% of the 1st day rental charges shall be applied and no additional amount will be paid for preparation & testing periods except rehearsal if required.
B10: 6 | C10: The above rates are for the function with on load working of DG set up to 5 hours per day and if the DG set is to be used continuously on load mote 5 hours per day then for each 5 KVA of DG set add Rs 60.00 per hour operation to be paid extra.
B11: 7 | C11: Necessary certificate from electrical inspector will be taken by concern Agency before 4 hours starting from function / rehearsal positively .
B12: 8 | C12: The rate for DG Set included transportation charges for up to 30 kms from Concern Division H.Q. to function place and back. Add Rs . 500/- for additional 30 kms. Block.
B13: 9 | C13: The items which are not included in SOR the higher charges should be derived as 10% of total cost of item for 1 st day.
B14: 10 | C14: All switchgears,cables,wires, fittings & Lamps with accessories etc must be ISI MARKED Positively.
B15: 11 | C15: Rates is inclusive of material, labour, supervision, liaison, transportation -overheads and All taxes including GSTexcept 1% labour cess.
B16: 11-1-1 | C16: Hire charges for providing erecting temp LED light 10 mm bulbs approved high glow with complete wiring with auto changer reverse and after good use dismantling.
C17: (A) Strip Light. (Minimum 38 Lamps / Mtr.) | D17: 1st Day /RMT | E17: 0 | F17: 21 | G17: =+E17+F17 -> 21
C18: (B) Series Light. (Minimum 5 Lamps / Mtr.) | D18: 1st Day /RMT | E18: 0 | F18: 3 | G18: =+E18+F18 -> 3
C19: (C) Rope Light. (Minimum 15 Lamps. / Mtr.) | D19: 1st Day /RMT | E19: 0 | F19: 7 | G19: =+E19+F19 -> 7
C20: (D) Decorative LED design light on board | D20: 1st Day /lamp | E20: 0 | F20: 1 | G20: =+E20+F20 -> 1
C21: (E) Decorative LED palm piece | D21: 1st Day /piece | E21: 0 | F21: 250 | G21: =+E21+F21 -> 250
B22: 11-1-2 | C22: Hire charges for providing erecting and dismantling temporary illumination, consisting of strip lights complete with holders, bulbs up to 40Watt lamp of different colours complete with necessary lead wires erected and dismantled. | D22: 1st Day / No | E22: 0 | F22: 3 | G22: =+E22+F22 -> 3
B23: 11-1-3-a | C23: Hire charges for providing erecting and dismantling temporary illumination consisting of the LED tube lights 22 watt minimum complete withlead wires | D23: 1st Day / No | E23: 0 | F23: 20 | G23: =+E23+F23 -> 20
B24: 11-1-3-b | C24: For use of decorative tube in place of simple tube | D24: 1st Day | E24: 0 | F24: 13 | G24: =+E24+F24 -> 13
B25: 11-1-4 | C25: Hire charges for providing erecting and dismantling temporary illumination consisting of flood light fitting up to 100 Watt complete with holders lead wires, incandescent lamp with different colours with indoor / outdoor type | D25: 1st Day /Nos | E25: 0 | F25: 17 | G25: =+E25+F25 -> 17
B26: 11-1-5 | C26: Hire charges for providing erecting and dismantling temporary illumination consisting of halogen fitting 500 Watt / 85 watt retrofit CFL lamp/60watt LED lamp with suitable size Al. reflector complete with holders tube and lead wires. (outdoor Type) | D26: 1st Day /Nos | E26: 0 | F26: 60 | G26: =+E26+F26 -> 60
B27: 11-1-6-b | C27: Hire charges for providing erecting and dismantling temporary illumination consisting of halogen fitting 1000 Watt complete with holders tube and lead wires. (Outdoor Type) | D27: 1st Day /Nos | E27: 0 | F27: 80 | G27: =+E27+F27 -> 80
B28: 11-1-7 | C28: Hire Charges for heavy duty flood light luminaire comprises die cast aluminium body with heat resistant toughened front glass, silicon rubber gasket, electromechanically brightened anodised aluminium reflector , hot deep galvanized M.S. cradle clamp with suitable size of necessary control gear box having choke, capacitor, holder, lamp etc. complete.
C29: (A) Suitable for One No. 70 watt HPSV / Metal helide lamp | D29: 1 St.Day./no | E29: 0 | F29: 193 | G29: 193
C30: (B)Suitable for One No. 150 watt HPSV / Metal helide lamp | D30: 1 St.Day./no | E30: 0 | F30: 270 | G30: 270
C31: (C)Suitable for One No. 250 watt HPSV / Metal helide lamp | D31: 1 St.Day./no | E31: 0 | F31: 300 | G31: 300
C32: (D)Suitable for One No. 400 watt HPSV / Metal helide lamp | D32: 1 St.Day./no | E32: 0 | F32: 483 | G32: 483
B33: 11-1-8 | C33: Hire charges for providing erecting and dismantling after use of good running condition for the HPSV street light fitting with necessary accessories and lamps with fixing arrangement as per direction of engineer incharge
C34: (a) suitable for 70 watt | D34: 1 St.Day./no | E34: 0 | F34: 115 | G34: 115
C35: (b) suitable for 150 watt | D35: 1 St.Day./no | E35: 0 | F35: 138 | G35: 138
C36: (b) suitable for 250 watt | D36: 1 St.Day./no | E36: 0 | F36: 174 | G36: 174
C37: (b) suitable for 400 watt | D37: 1 St.Day./no | E37: 0 | F37: 269 | G37: 269
B38: 11-1-9 | C38: Providing and fixing chaser to give running erected to strip light and min up to load of 5 KW | D38: 1 St.Day./no | E38: 0 | F38: 176 | G38: 176
B39: 11-1-10 | C39: Hire charges for providing, erecting and dismantling after use in good running condition for temp. arrangement of city colour HMI light with necessary KW capacity Lamps with its control panel and wiring and operating complete.
C40: (a) 2 / 2.50 Kw. | D40: 1 St.Day./no | E40: 0 | F40: =9500*1.1 -> 10450 | G40: =F40 -> 10450
C41: (a) 4.0 Kw. | D41: 1 St.Day./no | E41: 0 | F41: =15500*1.1 -> 17050 | G41: =F41 -> 17050
...

Sheet Sound
B2: CHAPTER-XI TEMPORARY ILLUMINATION,A/C,PUBLIC ADDRESS AUDIO/ VIDEO & STANDBY POWER SYSTEM
B3: (Rates included GST/Service Tax)
B4: NOTES
B5: 1 | C5: The rates for temporary D.G,sound ,E.I. ,A.C. , LED, TV, Multi media are applicable for 1st day including preparatory & testing period & no additional amount shall be paid for that but for rehearsal if ask by authority, additional amount shall be paid 25% of first day rental charges.
B6: 2 | C6: (i) For the second day of function , 40% of first day rent shall be considered. (ii) For each additional day after Second day of function but not exceeding 15 days, 15% of first day rental cost will be considered.
B7: 3 | C7: After 15 days 5% of 1st day rental cost will be limited do 80% of full rate of newly purchased equipments .For more than above days,it is necessary to have consent letter of administrative authority.
B8: 4 | C8: Testing of all temporary arrangement will be positively given before 12 hours start of function or rehearsal (if ask by concerned Authority) .
B9: 5 | C9: For D.G. set, rental rates are applicable for first day. (1)For next subsequently 7 days ,90% of first day rental charges will be applied (2)from 8th day ,80% of the 1st day rental charges shall be applied and no additional amount will be paid for preparation & testing periods except rehearsal if required.
B10: 6 | C10: The above rates are for the function with on load working of DG set up to 5 hours per day and if the DG set is to be used continuously on load mote 5 hours per day then for each 5 KVA of DG set add Rs 60.00 per hour operation to be paid extra.
B11: 7 | C11: Necessary certificate from electrical inspector will be taken by concern Agency before 4 hours starting from function / rehearsal positively .
B12: 8 | C12: The rate for DG Set included transportation charges for up to 30 kms from Concern Division H.Q. to function place and back. Add Rs . 500/- for additional 30 kms. Block.
B13: 9 | C13: The items which are not included in SOR the higher charges should be derived as 10% of total cost of item for 1 st day.
B14: 10 | C14: All switchgears,cables,wires, fittings & Lamps with accessories etc must be ISI MARKED Positively.
B15: 11 | C15: Rates is inclusive of material, labour, supervision, liaison, transportation -overheads and All taxes including GSTexcept 1% labour cess.
B16: 11-1-1 | C16: Hire charges for providing erecting temp LED light 10 mm bulbs approved high glow with complete wiring with auto changer reverse and after good use dismantling.
C17: (A) Strip Light. (Minimum 38 Lamps / Mtr.) | D17: 1st Day /RMT | E17: 0 | F17: 21 | G17: =+E17+F17 -> 21
C18: (B) Series Light. (Minimum 5 Lamps / Mtr.) | D18: 1st Day /RMT | E18: 0 | F18: 3 | G18: =+E18+F18 -> 3
C19: (C) Rope Light. (Minimum 15 Lamps. / Mtr.) | D19: 1st Day /RMT | E19: 0 | F19: 7 | G19: =+E19+F19 -> 7
C20: (D) Decorative LED design light on board | D20: 1st Day /lamp | E20: 0 | F20: 1 | G20: =+E20+F20 -> 1
C21: (E) Decorative LED palm piece | D21: 1st Day /piece | E21: 0 | F21: 250 | G21: =+E21+F21 -> 250
B22: 11-1-2 | C22: Hire charges for providing erecting and dismantling temporary illumination, consisting of strip lights complete with holders, bulbs up to 40Watt lamp of different colours complete with necessary lead wires erected and dismantled. | D22: 1st Day / No | E22: 0 | F22: 3 | G22: =+E22+F22 -> 3
B23: 11-1-3-a | C23: Hire charges for providing erecting and dismantling temporary illumination consisting of the LED tube lights 22 watt minimum complete withlead wires | D23: 1st Day / No | E23: 0 | F23: 20 | G23: =+E23+F23 -> 20
B24: 11-1-3-b | C24: For use of decorative tube in place of simple tube | D24: 1st Day | E24: 0 | F24: 13 | G24: =+E24+F24 -> 13
B25: 11-1-4 | C25: Hire charges for providing erecting and dismantling temporary illumination consisting of flood light fitting up to 100 Watt complete with holders lead wires, incandescent lamp with different colours with indoor / outdoor type | D25: 1st Day /Nos | E25: 0 | F25: 17 | G25: =+E25+F25 -> 17
B26: 11-1-5 | C26: Hire charges for providing erecting and dismantling temporary illumination consisting of halogen fitting 500 Watt / 85 watt retrofit CFL lamp/60watt LED lamp with suitable size Al. reflector complete with holders tube and lead wires. (outdoor Type) | D26: 1st Day /Nos | E26: 0 | F26: 60 | G26: =+E26+F26 -> 60
B27: 11-1-6-b | C27: Hire charges for providing erecting and dismantling temporary illumination consisting of halogen fitting 1000 Watt complete with holders tube and lead wires. (Outdoor Type) | D27: 1st Day /Nos | E27: 0 | F27: 80 | G27: =+E27+F27 -> 80
B28: 11-1-7 | C28: Hire Charges for heavy duty flood light luminaire comprises die cast aluminium body with heat resistant toughened front glass, silicon rubber gasket, electromechanically brightened anodised aluminium reflector , hot deep galvanized M.S. cradle clamp with suitable size of necessary control gear box having choke, capacitor, holder, lamp etc. complete.
C29: (A) Suitable for One No. 70 watt HPSV / Metal helide lamp | D29: 1 St.Day./no | E29: 0 | F29: 193 | G29: 193
C30: (B)Suitable for One No. 150 watt HPSV / Metal helide lamp | D30: 1 St.Day./no | E30: 0 | F30: 270 | G30: 270
C31: (C)Suitable for One No. 250 watt HPSV / Metal helide lamp | D31: 1 St.Day./no | E31: 0 | F31: 300 | G31: 300
C32: (D)Suitable for One No. 400 watt HPSV / Metal helide lamp | D32: 1 St.Day./no | E32: 0 | F32: 483 | G32: 483
B33: 11-1-8 | C33: Hire charges for providing erecting and dismantling after use of good running condition for the HPSV street light fitting with necessary accessories and lamps with fixing arrangement as per direction of engineer incharge
C34: (a) suitable for 70 watt | D34: 1 St.Day./no | E34: 0 | F34: 115 | G34: 115
C35: (b) suitable for 150 watt | D35: 1 St.Day./no | E35: 0 | F35: 138 | G35: 138
C36: (b) suitable for 250 watt | D36: 1 St.Day./no | E36: 0 | F36: 174 | G36: 174
C37: (b) suitable for 400 watt | D37: 1 St.Day./no | E37: 0 | F37: 269 | G37: 269
B38: 11-1-9 | C38: Providing and fixing chaser to give running erected to strip light and min up to load of 5 KW | D38: 1 St.Day./no | E38: 0 | F38: 176 | G38: 176
B39: 11-1-10 | C39: Hire charges for providing, erecting and dismantling after use in good running condition for temp. arrangement of city colour HMI light with necessary KW capacity Lamps with its control panel and wiring and operating complete.
C40: (a) 2 / 2.50 Kw. | D40: 1 St.Day./no | E40: 0 | F40: =9500*1.1 -> 10450 | G40: =F40 -> 10450
C41: (a) 4.0 Kw. | D41: 1 St.Day./no | E41: 0 | F41: =15500*1.1 -> 17050 | G41: =F41 -> 17050
...

Sheet chapter 11
B2: CHAPTER-XI TEMPORARY ILLUMINATION,A/C,PUBLIC ADDRESS AUDIO/ VIDEO & STANDBY POWER SYSTEM
B3: (Rates included GST/Service Tax)
B4: NOTES
B5: 1 | C5: The rates for temporary D.G,sound ,E.I. ,A.C. , LED, TV, Multi media are applicable for 1st day including preparatory & testing period & no additional amount shall be paid for that but for rehearsal if ask by authority, additional amount shall be paid 25% of first day rental charges.
B6: 2 | C6: (i) For the second day of function , 40% of first day rent shall be considered. (ii) For each additional day after Second day of function but not exceeding 15 days, 15% of first day rental cost will be considered.
B7: 3 | C7: After 15 days 5% of 1st day rental cost will be limited do 80% of full rate of newly purchased equipments .For more than above days,it is necessary to have consent letter of administrative authority.
B8: 4 | C8: Testing of all temporary arrangement will be positively given before 12 hours start of function or rehearsal (if ask by concerned Authority) .
B9: 5 | C9: For D.G. set, rental rates are applicable for first day. (1)For next subsequently 7 days ,90% of first day rental charges will be applied (2)from 8th day ,80% of the 1st day rental charges shall be applied and no additional amount will be paid for preparation & testing periods except rehearsal if required.
B10: 6 | C10: The above rates are for the function with on load working of DG set up to 5 hours per day and if the DG set is to be used continuously on load mote 5 hours per day then for each 5 KVA of DG set add Rs 60.00 per hour operation to be paid extra.
B11: 7 | C11: Necessary certificate from electrical inspector will be taken by concern Agency before 4 hours starting from function / rehearsal positively .
B12: 8 | C12: The rate for DG Set included transportation charges for up to 30 kms from Concern Division H.Q. to function place and back. Add Rs . 500/- for additional 30 kms. Block.
B13: 9 | C13: The items which are not included in SOR the higher charges should be derived as 10% of total cost of item for 1 st day.
B14: 10 | C14: All switchgears,cables,wires, fittings & Lamps with accessories etc must be ISI MARKED Positively.
B15: 11 | C15: Rates is inclusive of material, labour, supervision, liaison, transportation -overheads and All taxes including GSTexcept 1% labour cess.
B16: 11-1-1 | C16: Hire charges for providing erecting temp LED light 10 mm bulbs approved high glow with complete wiring with auto changer reverse and after good use dismantling.
C17: (A) Strip Light. (Minimum 38 Lamps / Mtr.) | D17: 1st Day /RMT | E17: 0 | F17: 21 | G17: =+E17+F17 -> 21
C18: (B) Series Light. (Minimum 5 Lamps / Mtr.) | D18: 1st Day /RMT | E18: 0 | F18: 3 | G18: =+E18+F18 -> 3
C19: (C) Rope Light. (Minimum 15 Lamps. / Mtr.) | D19: 1st Day /RMT | E19: 0 | F19: 7 | G19: =+E19+F19 -> 7
C20: (D) Decorative LED design light on board | D20: 1st Day /lamp | E20: 0 | F20: 1 | G20: =+E20+F20 -> 1
C21: (E) Decorative LED palm piece | D21: 1st Day /piece | E21: 0 | F21: 250 | G21: =+E21+F21 -> 250
B22: 11-1-2 | C22: Hire charges for providing erecting and dismantling temporary illumination, consisting of strip lights complete with holders, bulbs up to 40Watt lamp of different colours complete with necessary lead wires erected and dismantled. | D22: 1st Day / No | E22: 0 | F22: 3 | G22: =+E22+F22 -> 3
B23: 11-1-3-a | C23: Hire charges for providing erecting and dismantling temporary illumination consisting of the LED tube lights 22 watt minimum complete withlead wires | D23: 1st Day / No | E23: 0 | F23: 20 | G23: =+E23+F23 -> 20
B24: 11-1-3-b | C24: For use of decorative tube in place of simple tube | D24: 1st Day | E24: 0 | F24: 13 | G24: =+E24+F24 -> 13
B25: 11-1-4 | C25: Hire charges for providing erecting and dismantling temporary illumination consisting of flood light fitting up to 100 Watt complete with holders lead wires, incandescent lamp with different colours with indoor / outdoor type | D25: 1st Day /Nos | E25: 0 | F25: 17 | G25: =+E25+F25 -> 17
B26: 11-1-5 | C26: Hire charges for providing erecting and dismantling temporary illumination consisting of halogen fitting 500 Watt / 85 watt retrofit CFL lamp/60watt LED lamp with suitable size Al. reflector complete with holders tube and lead wires. (outdoor Type) | D26: 1st Day /Nos | E26: 0 | F26: 60 | G26: =+E26+F26 -> 60
B27: 11-1-6-b | C27: Hire charges for providing erecting and dismantling temporary illumination consisting of halogen fitting 1000 Watt complete with holders tube and lead wires. (Outdoor Type) | D27: 1st Day /Nos | E27: 0 | F27: 80 | G27: =+E27+F27 -> 80
B28: 11-1-7 | C28: Hire Charges for heavy duty flood light luminaire comprises die cast aluminium body with heat resistant toughened front glass, silicon rubber gasket, electromechanically brightened anodised aluminium reflector , hot deep galvanized M.S. cradle clamp with suitable size of necessary control gear box having choke, capacitor, holder, lamp etc. complete.
C29: (A) Suitable for One No. 70 watt HPSV / Metal helide lamp | D29: 1 St.Day./no | E29: 0 | F29: 193 | G29: 193
C30: (B)Suitable for One No. 150 watt HPSV / Metal helide lamp | D30: 1 St.Day./no | E30: 0 | F30: 270 | G30: 270
C31: (C)Suitable for One No. 250 watt HPSV / Metal helide lamp | D31: 1 St.Day./no | E31: 0 | F31: 300 | G31: 300
C32: (D)Suitable for One No. 400 watt HPSV / Metal helide lamp | D32: 1 St.Day./no | E32: 0 | F32: 483 | G32: 483
B33: 11-1-8 | C33: Hire charges for providing erecting and dismantling after use of good running condition for the HPSV street light fitting with necessary accessories and lamps with fixing arrangement as per direction of engineer incharge
C34: (a) suitable for 70 watt | D34: 1 St.Day./no | E34: 0 | F34: 115 | G34: 115
C35: (b) suitable for 150 watt | D35: 1 St.Day./no | E35: 0 | F35: 138 | G35: 138
C36: (b) suitable for 250 watt | D36: 1 St.Day./no | E36: 0 | F36: 174 | G36: 174
C37: (b) suitable for 400 watt | D37: 1 St.Day./no | E37: 0 | F37: 269 | G37: 269
B38: 11-1-9 | C38: Providing and fixing chaser to give running erected to strip light and min up to load of 5 KW | D38: 1 St.Day./no | E38: 0 | F38: 176 | G38: 176
B39: 11-1-10 | C39: Hire charges for providing, erecting and dismantling after use in good running condition for temp. arrangement of city colour HMI light with necessary KW capacity Lamps with its control panel and wiring and operating complete.
C40: (a) 2 / 2.50 Kw. | D40: 1 St.Day./no | E40: 0 | F40: =9500*1.1 -> 10450 | G40: =F40 -> 10450
C41: (a) 4.0 Kw. | D41: 1 St.Day./no | E41: 0 | F41: =15500*1.1 -> 17050 | G41: =F41 -> 17050
...
